---
title: L’instruction 'Throw' ne peut pas omettre l’opérande en dehors d’une instruction 'Catch' ou dans une instruction 'Finally'
ms.date: 07/20/2015
f1_keywords:
- vbc30666
- bc30666
helpviewer_keywords:
- BC30666
ms.assetid: a208a6ea-0e36-4bf1-8984-4de1a0e38a2a
ms.openlocfilehash: 17e7817c608e9c3513e0320b62f42410613f33b0
ms.sourcegitcommit: 0be8a279af6d8a43e03141e349d3efd5d35f8767
ms.translationtype: HT
ms.contentlocale: fr-FR
ms.lasthandoff: 04/18/2019
ms.locfileid: "59302489"
---
# <a name="throw-statement-cannot-omit-operand-outside-a-catch-statement-or-inside-a-finally-statement"></a>L’instruction 'Throw' ne peut pas omettre l’opérande en dehors d’une instruction 'Catch' ou dans une instruction 'Finally'
Les instructions`Throw` situées en dehors de l’instruction `Catch` doivent fournir le nom d’un objet exception.  
  
 **ID d’erreur :** BC30666  
  
## <a name="to-correct-this-error"></a>Pour corriger cette erreur  
  
1. Spécifiez le nom d’un objet d’exception dérivé de `System.Exception`.  
  
2. Restructurez votre code pour que l’instruction `Throw` se trouve dans un bloc `Catch` .  
  
## <a name="see-also"></a>Voir aussi

- [Throw (instruction)](../../visual-basic/language-reference/statements/throw-statement.md)
- [Try...Catch...Finally (instruction)](../../visual-basic/language-reference/statements/try-catch-finally-statement.md)
- <xref:System.Exception?displayProperty=nameWithType>
- [Gestion et levée d’exceptions dans .NET](../../standard/exceptions/index.md)
